<robot name="gripper">
  <link name="world" />
  <link name="base">
    <inertial>
       <origin xyz="0 0 0" rpy="0 0 0" />
       <mass value="0.1" />
       <inertia ixx="0.001" ixy="0.001" ixz="0.001" iyy="0.001" iyz="0.001" izz="0.001" />
    </inertial>
    <visual>
      <origin rpy="0 0 0" xyz="0 0 0" />
      <geometry>
        <box size="1 0.1 0.1" />
      </geometry>
      <material name="grey">
        <color rgba="0.4 0.4 0.4 1" />
      </material>
    </visual>
  </link>
  <joint name="base" type="fixed">
    <parent link="world" />
    <child link="base" />
    <origin rpy="0.0 0.0 0" xyz="0 0 1" />
  </joint>
  <link name="left_rod">
    <inertial>
       <origin xyz="0 0 0.25" rpy="0 0 0" />
       <mass value="0.1" />
       <inertia ixx="0.001" ixy="0.001" ixz="0.001" iyy="0.001" iyz="0.001" izz="0.001" />
    </inertial>
    <visual>
      <origin rpy="0 0 0" xyz="0 0 0.25" />
      <geometry>
        <box size="0.1 0.1 0.5" />
      </geometry>
      <material name="grey">
        <color rgba="0.4 0.4 0.4 1" />
      </material>
    </visual>
  </link>
  <joint name="left_rod" type="continuous">
    <parent link="base" />
    <child link="left_rod" />
    <origin rpy="0.0 0.0 0" xyz="-0.5 0 0" />
    <axis xyz="0 1 0"/>
  </joint>
  <link name="top_rod">
    <inertial>
       <origin xyz="0.5 0 0" rpy="0 0 0" />
       <mass value="0.1" />
       <inertia ixx="0.001" ixy="0.001" ixz="0.001" iyy="0.001" iyz="0.001" izz="0.001" />
    </inertial>
    <visual>
      <origin rpy="0 0 0" xyz="0.5 0 0" />
      <geometry>
        <box size="1 0.1 0.1" />
      </geometry>
      <material name="grey">
        <color rgba="0.4 0.4 0.4 1" />
      </material>
    </visual>
  </link>
  <joint name="top_rod" type="continuous">
    <parent link="left_rod" />
    <child link="top_rod" />
    <origin rpy="0.0 0.0 0" xyz="0 0 0.5" />
    <axis xyz="0 1 0"/>
  </joint>
  <link name="right_rod">
    <inertial>
       <origin xyz="0 0 0.25" rpy="0 0 0" />
       <mass value="0.1" />
       <inertia ixx="0.001" ixy="0.001" ixz="0.001" iyy="0.001" iyz="0.001" izz="0.001" />
    </inertial>
    <visual>
      <origin rpy="0 0 0" xyz="0 0 0.25" />
      <geometry>
        <box size="0.1 0.1 0.5" />
      </geometry>
      <material name="grey">
        <color rgba="0.4 0.4 0.4 1" />
      </material>
    </visual>
  </link>
  <joint name="right_rod" type="continuous">
    <parent link="base" />
    <child link="right_rod" />
    <origin rpy="0.0 0.0 0" xyz="0.5 0 0" />
    <axis xyz="0 1 0"/>
  </joint>
</robot>